Workbook

Sheet Components & Wiki v1
A1: ='Components Data Source'!A1 -> Name | B1: ='Components Data Source'!B1 -> GUID | C1: ='Components Data Source'!C1 -> FCPX Name | D1: ='Components Data Source'!D1 -> Source | E1: New GUI(Blue is OK as new GUID may not be required) | F1: Completed | G1: Icon | H1: Notes | I1: ='Components Data Source'!I1 -> Peripherals | J1: ='Components Data Source'!J1 -> Dynamic | K1: ='Components Data Source'!K1 -> Embedded | L1: ='Components Data Source'!L1 -> AppDeveloper | M1: ="Converted to v10, W=WIP. (Yes = "&COUNTIF(M2:M603, "Y")&"/"&(COUNTIF(M2:M603, "N")+COUNTIF(M2:M603, "W")+COUNTIF(M2:M603, "Y"))&")" -> Converted to v10, W=WIP. (Yes = 0/602) | N1: ='Components Data Source'!M1 -> URL | O1: ="Wiki Link working Via Help, 3rd pass. Tot Checked ="&(COUNTIF(O2:O603,"N")+COUNTIF(O2:O603,"Y")+COUNTIF(O2:O603,"I")+COUNTIF(O2:O603,"O"))&", GN:OK="&COUNTIF(O2:O603,"Y")&", YL:Issue e.g [[File:]="&COUNTIF(O2:O603,"I")&", OR:org format="&(COUNTIF(O2:O603,"O")&", RD:Not Working="&(COUNTIF(O2:O603,"N"))) -> Wiki Link working Via Help, 3rd pass. Tot Checked =592, GN:OK=533, YL:Issue e.g [[File:]=29, OR:org format=28, RD:Not Working=2 | P1: Notes Column N. | Q1: Only App Developer | R1: ="Conversion Required (Cells entered = "&COUNTIF(R2:R603, "Y")+COUNTIF(R2:R603, "N")&"/"&COUNTIF(R2:R603, "Y")+COUNTIF(R2:R603, "N")+COUNTIF(R2:R603, "Q")+COUNTIF(R2:R603, "")&")" -> Conversion Required (Cells entered = 589/600) | S1: ="Converted or 2D only? (Yes = "&COUNTIFS(S2:S613,"Y",R2:R613,"Y")&"/"&(COUNTIFS(R2:R613,"Y"))&")" -> Converted or 2D only? (Yes = 263/265) | T1: Console Required | U1: Comms Ind | V1: Provide (Left) Icon | W1: Borrow (Right) Icon | X1: Component Uploaded to OneDrive | Y1: ="Converted component Loads and looks + functions correctly (Yes = "&COUNTIF(Y2:Y603, "Y")&"/"&COUNTIF(Y2:Y603, "Y")+COUNTIF(Y2:Y603, "N")+COUNTIF(Y2:Y603, "A")&")" -> Converted component Loads and looks + functions correctly (Yes = 218/262) | Z1: Comps uploading to server: Grn = Ready, Rd = Not Ready, Bl conversion not required & Or = Awaiting for approval. | AA1: Notes to Ben or Requires Help From Ben? | AB1: Martins Comments | AC1: Bens Comments | AD1: ="Wiki Link working Via Help. Bl = Not applic. (Not working = "&COUNTIF(AD2:AD603, "N")&"/"&(COUNTIF(AD2:AD603, "N")+COUNTIF(AD2:AD603, "Y"))&")" -> Wiki Link working Via Help. Bl = Not applic. (Not working = 46/593) | AE1: Example/Scenario Added. Bl= not Applicable | AF1: Circuit Diagram Added Bl= not Applicable | AG1: Example Flowchart/Diagram Added 2nd run Bl= not Applicable | AH1: Notes AC to AF | AI1: Components Usage | AJ1: ="Component tested (HW & Sim if appl ) Or = awaiting to test (Tested = "&COUNTIF(AJ2:AJ603, "Y")&"/"&(COUNTIF(AJ2:AJ603, "Y")+COUNTIF(AJ2:AJ603, "A"))&")" -> Component tested (HW & Sim if appl ) Or = awaiting to test (Tested = 13/541)
A2: ='Components Data Source'!A2 -> DAC (AD5662) | B2: ='Components Data Source'!B2 -> 3D87FFE9-97C1-4013-A2CD-82C24D0CCB48 | C2: ='Components Data Source'!C2 -> ADC_AD5662.fcpx | D2: ='Components Data Source'!D2 -> Components\IO_Source\outputs\DAC_AD5662.fcfx | E2: ='Components Data Source'!E2 -> COMMSA | F2: ='Components Data Source'!F2 -> ANALOG OUTPUT | G2: ='Components Data Source'!G2 -> 0 | H2: ='Components Data Source'!H2 -> 0 | ... L2: ='Components Data Source'!L2 -> 0 | M2: N | N2: =HYPERLINK('Components Data Source'!M2) -> https://www.flowcode.co.uk/wiki/index.php?title=Component:_ID_3d87ffe9_97c1_4013_a2cd_82c24d0ccb48 | O2: Y | Q2: =IF(L2=1,IF(K2=1,"",1),"") | R2: Y | S2: Y | T2: Y | U2: Y | V2: None | W2: SPI | X2: Y | Y2: Y | Z2: =IF(AND(R2="Y",Y2="Y"),1,IF(R2="N",2,IF(R2="",4,IF(Y2="A",3,0)))) -> 1 | AD2: Y | AE2: Y | AF2: Y | AG2: Y | AI2: =VLOOKUP(B2,'Components Usage'!A$2:C$603,3,FALSE) -> 0 | AJ2: A | BI2: Column1
A3: ='Components Data Source'!A3 -> ADC (AD7680) | B3: ='Components Data Source'!B3 -> 937E425E-21C0-4B08-8D8F-0BF80A6391D2 | C3: ='Components Data Source'!C3 -> ADC_AD7680.fcpx | D3: ='Components Data Source'!D3 -> Components\IO_Source\adc\ExternalADC_AD7680.fcfx | E3: ='Components Data Source'!E3 -> COMMSA | F3: ='Components Data Source'!F3 -> ANALOG INPUT | G3: ='Components Data Source'!G3 -> 0 | H3: ='Components Data Source'!H3 -> 0 | ... L3: ='Components Data Source'!L3 -> 0 | M3: N | N3: =HYPERLINK('Components Data Source'!M3) -> https://www.flowcode.co.uk/wiki/index.php?title=Component:_ID_937e425e_21c0_4b08_8d8f_0bf80a6391d2 | O3: Y | Q3: =IF(L3=1,IF(K3=1,"",1),"") | R3: Y | S3: Y | T3: Y | U3: Y | V3: None | W3: SPI | X3: Y | Y3: Y | Z3: =IF(AND(R3="Y",Y3="Y"),1,IF(R3="N",2,IF(R3="",4,IF(Y3="A",3,0)))) -> 1 | AD3: Y | AE3: Y | AF3: Y | AG3: Y | AI3: =VLOOKUP(B3,'Components Usage'!A$2:C$603,3,FALSE) -> 3 | AJ3: A | AQ3: Select
A4: ='Components Data Source'!A4 -> DSP Audio Input (EB085) | B4: ='Components Data Source'!B4 -> 87D8BAD5-6392-41FB-B370-D9B2C0F8F13F | C4: ='Components Data Source'!C4 -> ADC_EB085.fcpx | D4: ='Components Data Source'!D4 -> Components\IO_Source\adc\ExternalADC_AD7680_EB085.fcfx | E4: ='Components Data Source'!E4 -> COMMSA | F4: ='Components Data Source'!F4 -> E-BLOCKS 1 | G4: ='Components Data Source'!G4 -> 0 | H4: ='Components Data Source'!H4 -> 0 | ... L4: ='Components Data Source'!L4 -> 0 | M4: N | N4: =HYPERLINK('Components Data Source'!M4) -> https://www.flowcode.co.uk/wiki/index.php?title=Component:_ID_87d8bad5_6392_41fb_b370_d9b2c0f8f13f | O4: O | Q4: =IF(L4=1,IF(K4=1,"",1),"") | R4: Y | S4: Y | T4: Y | U4: Y | V4: None | W4: SPI | X4: Y | Y4: Y | Z4: =IF(AND(R4="Y",Y4="Y"),1,IF(R4="N",2,IF(R4="",4,IF(Y4="A",3,0)))) -> 1 | AB4: Will modify wiki when new rage has replaced current range. | AD4: Y | AE4: N | AF4: N | AG4: N | AI4: =VLOOKUP(B4,'Components Usage'!A$2:C$603,3,FALSE) -> 13 | AJ4: A | AQ4: None
A5: ='Components Data Source'!A5 -> ADC (MCP356X) | B5: ='Components Data Source'!B5 -> 235FD689-BFD1-4C4A-A918-6C3C36E9A49F | C5: ='Components Data Source'!C5 -> ADC_MCP356X.fcpx | D5: ='Components Data Source'!D5 -> Components\IO_Source\adc\ExternalADC_MCP356X.fcfx | E5: ='Components Data Source'!E5 -> FREE | F5: ='Components Data Source'!F5 -> ANALOG INPUT | G5: ='Components Data Source'!G5 -> 0 | H5: ='Components Data Source'!H5 -> 0 | ... L5: ='Components Data Source'!L5 -> 0 | M5: N | N5: =HYPERLINK('Components Data Source'!M5) -> https://www.flowcode.co.uk/wiki/index.php?title=Component:_ID_235fd689_bfd1_4c4a_a918_6c3c36e9a49f | O5: Y | Q5: =IF(L5=1,IF(K5=1,"",1),"") | R5: Y | S5: Y | T5: Y | V5: None | W5: SPI | X5: Y | Y5: Y | Z5: =IF(AND(R5="Y",Y5="Y"),1,IF(R5="N",2,IF(R5="",4,IF(Y5="A",3,0)))) -> 1 | AD5: Y | AF5: N | AG5: N | AI5: =VLOOKUP(B5,'Components Usage'!A$2:C$603,3,FALSE) -> 0 | AQ5: NetComms
A6: ='Components Data Source'!A6 -> Infrared Array AMG88xx | B6: ='Components Data Source'!B6 -> E1D52EFB-00D4-4E19-BA4C-29B292535EA1 | C6: ='Components Data Source'!C6 -> AMG88xx.fcpx | D6: ='Components Data Source'!D6 -> Components\IO_Source\Sensors\AMG88.fcfx | E6: ='Components Data Source'!E6 -> SENSORS | F6: ='Components Data Source'!F6 -> LIGHT | G6: ='Components Data Source'!G6 -> 0 | H6: ='Components Data Source'!H6 -> 0 | ... L6: ='Components Data Source'!L6 -> 1 | M6: N | N6: =HYPERLINK('Components Data Source'!M6) -> https://www.flowcode.co.uk/wiki/index.php?title=Component:_ID_e1d52efb_00d4_4e19_ba4c_29b292535ea1 | O6: Y | Q6: =IF(L6=1,IF(K6=1,"",1),"") | R6: Y | S6: Y | T6: N | U6: N | V6: None | W6: None | X6: Y | Y6: Y | Z6: =IF(AND(R6="Y",Y6="Y"),1,IF(R6="N",2,IF(R6="",4,IF(Y6="A",3,0)))) -> 1 | AD6: Y | AE6: N | AF6: N | AG6: N | AI6: =VLOOKUP(B6,'Components Usage'!A$2:C$603,3,FALSE) -> 3 | AJ6: A | AQ6: TCP/IP
A7: ='Components Data Source'!A7 -> Accelerometer(EB068) | B7: ='Components Data Source'!B7 -> B81925B1-7504-4D77-AC90-3A4FA700FCC4 | C7: ='Components Data Source'!C7 -> Accelerometer_EB068.fcpx | D7: ='Components Data Source'!D7 -> Components\IO_Source\Sensors\Accelerometer_EB068.fcfx | E7: ='Components Data Source'!E7 -> SENSORS | F7: ='Components Data Source'!F7 -> E-BLOCKS 1 | G7: ='Components Data Source'!G7 -> 0 | H7: ='Components Data Source'!H7 -> 0 | ... L7: ='Components Data Source'!L7 -> 0 | M7: N | N7: =HYPERLINK('Components Data Source'!M7) -> https://www.flowcode.co.uk/wiki/index.php?title=Component:_ID_b81925b1_7504_4d77_ac90_3a4fa700fcc4 | O7: O | Q7: =IF(L7=1,IF(K7=1,"",1),"") | R7: Y | S7: Y | T7: Y | U7: Y | V7: None | W7: I2C | X7: Y | Y7: A | Z7: =IF(AND(R7="Y",Y7="Y"),1,IF(R7="N",2,IF(R7="",4,IF(Y7="A",3,0)))) -> 3 | AB7: Not happy with console tabs. Transaction Conversion Required for both I2C & SPI. Icon misisng. No icons below .Return=UpdateXYZData(). Fixed & Competed I2C transaction 16/8/21 | AD7: Y | AE7: N | AF7: N | AG7: N | AI7: =VLOOKUP(B7,'Components Usage'!A$2:C$603,3,FALSE) -> 0 | AJ7: A | AQ7: GLCD
A8: ='Components Data Source'!A8 -> Accelerometer 3-Axis(LIS3LV02DQ) | B8: ='Components Data Source'!B8 -> 72F0A8C3-2B8F-4723-B22A-4A81873E5151 | C8: ='Components Data Source'!C8 -> Accelerometer_LIS3LV02DQ.fcpx | D8: ='Components Data Source'!D8 -> Components\IO_Source\Sensors\Accelerometer_LIS3LV0DQ.fcfx | E8: ='Components Data Source'!E8 -> SENSORS | F8: ='Components Data Source'!F8 -> MOVEMENT &AMP; ORIENTATION | G8: ='Components Data Source'!G8 -> 0 | H8: ='Components Data Source'!H8 -> 0 | ... L8: ='Components Data Source'!L8 -> 1 | M8: N | N8: =HYPERLINK('Components Data Source'!M8) -> https://www.flowcode.co.uk/wiki/index.php?title=Component:_ID_72f0a8c3_2b8f_4723_b22a_4a81873e5151 | O8: Y | P8: Was 'N' Fixed MW | Q8: =IF(L8=1,IF(K8=1,"",1),"") | R8: Y | S8: Y | T8: Y | U8: Y | V8: None | W8: I2C | X8: Y | Y8: Y | Z8: =IF(AND(R8="Y",Y8="Y"),1,IF(R8="N",2,IF(R8="",4,IF(Y8="A",3,0)))) -> 1 | AA8: N | AB8: Requires Transaction conversion for both I2C and SPI. Wrong o/p icon - Corrected 10/06/21. Changed injector ref within properties to API 15/6/21 | AC8: Just do transaction conversion for I2C, SPI can stay as is and will work on ESP/ARM devices | AD8: Y | AE8: N | AF8: N | AG8: N | AI8: =VLOOKUP(B8,'Components Usage'!A$2:C$603,3,FALSE) -> 0 | AJ8: A | AQ8: File
A9: ='Components Data Source'!A9 -> Accelerometer 3-Axis(MMA8452Q) | B9: ='Components Data Source'!B9 -> 2C716005-E9B5-46E3-86F9-30E5268341A9 | C9: ='Components Data Source'!C9 -> Accelerometer_MMA8452Q.fcpx | D9: ='Components Data Source'!D9 -> Components\IO_Source\Sensors\Accelerometer_MMA8452Q.fcfx | E9: ='Components Data Source'!E9 -> SENSORS | F9: ='Components Data Source'!F9 -> MOVEMENT &AMP; ORIENTATION | G9: ='Components Data Source'!G9 -> 0 | H9: ='Components Data Source'!H9 -> 0 | ... L9: ='Components Data Source'!L9 -> 1 | M9: N | N9: =HYPERLINK('Components Data Source'!M9) -> https://www.flowcode.co.uk/wiki/index.php?title=Component:_ID_2c716005_e9b5_46e3_86f9_30e5268341a9 | O9: Y | P9: Was 'N' Fixed MW | Q9: =IF(L9=1,IF(K9=1,"",1),"") | R9: Y | S9: Y | T9: Y | U9: Y | V9: None | W9: I2C | X9: Y | Y9: A | Z9: =IF(AND(R9="Y",Y9="Y"),1,IF(R9="N",2,IF(R9="",4,IF(Y9="A",3,0)))) -> 3 | AB9: Both I2C & SPI added, but only using I2C. Wrong o/p icon - Corrected 10/06/21 Changed injector ref within properties to API 15/6/21 | AD9: N | AF9: N | AG9: N | AI9: =VLOOKUP(B9,'Components Usage'!A$2:C$603,3,FALSE) -> 1 | AQ9: I2C
A10: ='Components Data Source'!A10 -> Ambient Light(BH1750FVI) | B10: ='Components Data Source'!B10 -> E08872A7-6962-4B61-BCCA-71389F8ED8D7 | C10: ='Components Data Source'!C10 -> AmbientLight.fcpx | D10: ='Components Data Source'!D10 -> Components\IO_Source\Sensors\AmbientLight_BH1750FVI.fcfx | E10: ='Components Data Source'!E10 -> SENSORS | F10: ='Components Data Source'!F10 -> LIGHT | G10: ='Components Data Source'!G10 -> 0 | H10: ='Components Data Source'!H10 -> 0 | ... L10: ='Components Data Source'!L10 -> 0 | M10: N | N10: =HYPERLINK('Components Data Source'!M10) -> https://www.flowcode.co.uk/wiki/index.php?title=Component:_ID_e08872a7_6962_4b61_bcca_71389f8ed8d7 | O10: Y | Q10: =IF(L10=1,IF(K10=1,"",1),"") | R10: Y | S10: Y | T10: Y | U10: Y | V10: None | W10: I2C | X10: Y | Y10: Y | Z10: =IF(AND(R10="Y",Y10="Y"),1,IF(R10="N",2,IF(R10="",4,IF(Y10="A",3,0)))) -> 1 | AB10: BH1750 Keyword requires adding. Added. | AD10: N | AF10: N | AG10: N | AI10: =VLOOKUP(B10,'Components Usage'!A$2:C$603,3,FALSE) -> 1 | AQ10: SPI
A11: ='Components Data Source'!A11 -> Area Chart | B11: ='Components Data Source'!B11 -> A907D905-5879-48F3-9ADD-369A2F4E164F | C11: ='Components Data Source'!C11 -> AreaChart.fcpx | D11: ='Components Data Source'!D11 -> Components\IO_Source\2dGDI\ChartArea.fcfx | E11: ='Components Data Source'!E11 -> FREE | F11: ='Components Data Source'!F11 -> CHARTS | G11: ='Components Data Source'!G11 -> CHARTS | H11: ='Components Data Source'!H11 -> 0 | ... L11: ='Components Data Source'!L11 -> 1 | M11: N | N11: =HYPERLINK('Components Data Source'!M11) -> https://www.flowcode.co.uk/wiki/index.php?title=Component:_ID_a907d905_5879_48f3_9add_369a2f4e164f | O11: Y | Q11: =IF(L11=1,IF(K11=1,"",1),"") | R11: N | V11: Select | W11: Select | Z11: =IF(AND(R11="Y",Y11="Y"),1,IF(R11="N",2,IF(R11="",4,IF(Y11="A",3,0)))) -> 2 | AD11: N | AF11: N | AG11: N | AI11: =VLOOKUP(B11,'Components Usage'!A$2:C$603,3,FALSE) -> 0 | AQ11: UART
A12: ='Components Data Source'!A12 -> Auto Version Identifier | B12: ='Components Data Source'!B12 -> 1911D96C-78DD-414A-B23C-6691FB19F63F | C12: ='Components Data Source'!C12 -> AutoVersionID.fcpx | D12: ='Components Data Source'!D12 -> Components\IO_Source\AutoVersionID.fcfx | E12: ='Components Data Source'!E12 -> STORAGE | F12: ='Components Data Source'!F12 -> STORAGE | G12: ='Components Data Source'!G12 -> 0 | H12: ='Components Data Source'!H12 -> 0 | ... L12: ='Components Data Source'!L12 -> 1 | M12: N | N12: =HYPERLINK('Components Data Source'!M12) -> https://www.flowcode.co.uk/wiki/index.php?title=Component:_ID_1911d96c_78dd_414a_b23c_6691fb19f63f | O12: Y | Q12: =IF(L12=1,IF(K12=1,"",1),"") | R12: N | V12: Select | W12: Select | Z12: =IF(AND(R12="Y",Y12="Y"),1,IF(R12="N",2,IF(R12="",4,IF(Y12="A",3,0)))) -> 2 | AD12: Y | AE12: Y | AF12: A | AG12: Y | AI12: =VLOOKUP(B12,'Components Usage'!A$2:C$603,3,FALSE) -> 36 | AJ12: Y | AQ12: API
A13: ='Components Data Source'!A13 -> BBC News | B13: ='Components Data Source'!B13 -> 72CD9559-26F7-4FFD-984C-CF3A82A6DB16 | C13: ='Components Data Source'!C13 -> BBCNews.fcpx | D13: ='Components Data Source'!D13 -> Components\IO_Source\IoT\BBCNews.fcfx | E13: ='Components Data Source'!E13 -> COMMSC | F13: ='Components Data Source'!F13 -> COMMS: IOT/CLOUD | G13: ='Components Data Source'!G13 -> 0 | H13: ='Components Data Source'!H13 -> 0 | ... L13: ='Components Data Source'!L13 -> 1 | M13: N | N13: =HYPERLINK('Components Data Source'!M13) -> https://www.flowcode.co.uk/wiki/index.php?title=Component:_ID_72cd9559_26f7_4ffd_984c_cf3a82a6db16 | O13: Y | Q13: =IF(L13=1,IF(K13=1,"",1),"") | R13: Y | S13: Y | T13: N | U13: Y | V13: None | W13: NetComms | X13: Y | Y13: Y | Z13: =IF(AND(R13="Y",Y13="Y"),1,IF(R13="N",2,IF(R13="",4,IF(Y13="A",3,0)))) -> 1 | AB13: References to weather. Fixed 08/06/21 | AD13: Y | AE13: N | AF13: A | AG13: N | AI13: =VLOOKUP(B13,'Components Usage'!A$2:C$603,3,FALSE) -> 1 | AJ13: A | AQ13: 1Wire API
A14: ='Components Data Source'!A14 -> BBC Weather Observation | B14: ='Components Data Source'!B14 -> BF90426C-1763-4A7A-BE5C-B3E442E3F6D8 | C14: ='Components Data Source'!C14 -> BBCWeather.fcpx | D14: ='Components Data Source'!D14 -> Components\IO_Source\IoT\BBCWeatherObservation.fcfx | E14: ='Components Data Source'!E14 -> COMMSC | F14: ='Components Data Source'!F14 -> COMMS: IOT/CLOUD | G14: ='Components Data Source'!G14 -> 0 | H14: ='Components Data Source'!H14 -> 0 | ... L14: ='Components Data Source'!L14 -> 1 | M14: N | N14: =HYPERLINK('Components Data Source'!M14) -> https://www.flowcode.co.uk/wiki/index.php?title=Component:_ID_bf90426c_1763_4a7a_be5c_b3e442e3f6d8 | O14: Y | R14: Y | S14: Y | T14: N | U14: Y | V14: None | W14: NetComms | X14: N | Y14: Y | Z14: =IF(AND(R14="Y",Y14="Y"),1,IF(R14="N",2,IF(R14="",4,IF(Y14="A",3,0)))) -> 1 | AD14: Y | AE14: Y | AF14: A | AG14: Y | AI14: =VLOOKUP(B14,'Components Usage'!A$2:C$603,3,FALSE) -> 1 | AJ14: A | AQ14: 1Wire
A15: ='Components Data Source'!A15 -> BBC Weather Forecast | B15: ='Components Data Source'!B15 -> DF96FFA1-4D36-453A-8877-758F68A2676C | C15: ='Components Data Source'!C15 -> BBCWeatherForecast.fcpx | D15: ='Components Data Source'!D15 -> Components\IO_Source\IoT\BBCWeatherForecast.fcfx | E15: ='Components Data Source'!E15 -> COMMSC | F15: ='Components Data Source'!F15 -> COMMS: IOT/CLOUD | G15: ='Components Data Source'!G15 -> 0 | H15: ='Components Data Source'!H15 -> 0 | ... L15: ='Components Data Source'!L15 -> 1 | M15: N | N15: =HYPERLINK('Components Data Source'!M15) -> https://www.flowcode.co.uk/wiki/index.php?title=Component:_ID_df96ffa1_4d36_453a_8877_758f68a2676c | O15: Y | Q15: =IF(L15=1,IF(K15=1,"",1),"") | R15: Y | S15: Y | T15: N | U15: Y | V15: None | W15: NetComms | X15: Y | Y15: Y | Z15: =IF(AND(R15="Y",Y15="Y"),1,IF(R15="N",2,IF(R15="",4,IF(Y15="A",3,0)))) -> 1 | AB15: No conponent icon Fixed 08/06/21 | AD15: Y | AE15: Y | AF15: A | AG15: Y | AI15: =VLOOKUP(B15,'Components Usage'!A$2:C$603,3,FALSE) -> 9 | AJ15: A
A16: ='Components Data Source'!A16 -> Bar Chart | B16: ='Components Data Source'!B16 -> 60B296CD-5B02-4C9C-9239-CCA36238F480 | C16: ='Components Data Source'!C16 -> BarChart.fcpx | D16: ='Components Data Source'!D16 -> Components\IO_Source\2dGDI\ChartBar.fcfx | E16: ='Components Data Source'!E16 -> FREE | F16: ='Components Data Source'!F16 -> CHARTS | G16: ='Components Data Source'!G16 -> CHARTS | H16: ='Components Data Source'!H16 -> 0 | ... L16: ='Components Data Source'!L16 -> 1 | M16: N | N16: =HYPERLINK('Components Data Source'!M16) -> https://www.flowcode.co.uk/wiki/index.php?title=Component:_ID_60b296cd_5b02_4c9c_9239_cca36238f480 | O16: Y | Q16: =IF(L16=1,IF(K16=1,"",1),"") | R16: N | V16: Select | W16: Select | Z16: =IF(AND(R16="Y",Y16="Y"),1,IF(R16="N",2,IF(R16="",4,IF(Y16="A",3,0)))) -> 2 | AD16: N | AF16: A | AG16: N | AI16: =VLOOKUP(B16,'Components Usage'!A$2:C$603,3,FALSE) -> 1
A17: ='Components Data Source'!A17 -> Barometer (DPS310) | B17: ='Components Data Source'!B17 -> CA60C1D2-FB77-4E3E-9D01-C4496D35DB1E | C17: ='Components Data Source'!C17 -> Barometer_DPS310.fcpx | D17: ='Components Data Source'!D17 -> Components\IO_Source\Sensors\Pressure_Sensor_DPS310.fcfx | E17: ='Components Data Source'!E17 -> SENSORS | F17: ='Components Data Source'!F17 -> ENVIRONMENTAL | G17: ='Components Data Source'!G17 -> 0 | H17: ='Components Data Source'!H17 -> 0 | ... L17: ='Components Data Source'!L17 -> 1 | M17: N | N17: =HYPERLINK('Components Data Source'!M17) -> https://www.flowcode.co.uk/wiki/index.php?title=Component:_ID_ca60c1d2_fb77_4e3e_9d01_c4496d35db1e | O17: Y | Q17: =IF(L17=1,IF(K17=1,"",1),"") | R17: Y | S17: Y | V17: Select | W17: Select | Y17: Y | Z17: =IF(AND(R17="Y",Y17="Y"),1,IF(R17="N",2,IF(R17="",4,IF(Y17="A",3,0)))) -> 1 | AD17: Y | AE17: N | AF17: N | AG17: N | AI17: =VLOOKUP(B17,'Components Usage'!A$2:C$603,3,FALSE) -> 0 | AJ17: A
A18: ='Components Data Source'!A18 -> Base2dChart | B18: ='Components Data Source'!B18 -> 1286CA5C-6453-4A92-9CCE-C6BA47457A69 | C18: ='Components Data Source'!C18 -> Base2dChart.fcpx | D18: ='Components Data Source'!D18 -> Components\IO_Source\2dGDI\Base2dChart.fcfx | E18: ='Components Data Source'!E18 -> FREE | F18: ='Components Data Source'!F18 -> DEVELOPMENT | G18: ='Components Data Source'!G18 -> 0 | H18: ='Components Data Source'!H18 -> 0 | ... L18: ='Components Data Source'!L18 -> 1 | M18: N | N18: =HYPERLINK('Components Data Source'!M18) -> https://www.flowcode.co.uk/wiki/index.php?title=Component:_ID_1286ca5c_6453_4a92_9cce_c6ba47457a69 | O18: A | Q18: =IF(L18=1,IF(K18=1,"",1),"") | R18: N | V18: Select | W18: Select | Z18: =IF(AND(R18="Y",Y18="Y"),1,IF(R18="N",2,IF(R18="",4,IF(Y18="A",3,0)))) -> 2 | AD18: A | AF18: N | AG18: N | AI18: =VLOOKUP(B18,'Components Usage'!A$2:C$603,3,FALSE) -> 1
A19: ='Components Data Source'!A19 -> Base2dGauge | B19: ='Components Data Source'!B19 -> B9285F96-06E8-4CDD-B0E2-A413F5150F1A | C19: ='Components Data Source'!C19 -> Base2dGauge.fcpx | D19: ='Components Data Source'!D19 -> Components\IO_Source\2dGDI\Base2dGauge.fcfx | E19: ='Components Data Source'!E19 -> FREE | F19: ='Components Data Source'!F19 -> DEVELOPMENT | G19: ='Components Data Source'!G19 -> 0 | H19: ='Components Data Source'!H19 -> 0 | ... L19: ='Components Data Source'!L19 -> 1 | M19: N | N19: =HYPERLINK('Components Data Source'!M19) -> https://www.flowcode.co.uk/wiki/index.php?title=Component:_ID_b9285f96_06e8_4cdd_b0e2_a413f5150f1a | O19: A | Q19: =IF(L19=1,IF(K19=1,"",1),"") | R19: N | V19: Select | W19: Select | Z19: =IF(AND(R19="Y",Y19="Y"),1,IF(R19="N",2,IF(R19="",4,IF(Y19="A",3,0)))) -> 2 | AD19: A | AF19: A | AG19: N | AI19: =VLOOKUP(B19,'Components Usage'!A$2:C$603,3,FALSE) -> 2
A20: ='Components Data Source'!A20 -> Base2dObject | B20: ='Components Data Source'!B20 -> E11146D4-2D40-4BE6-95CC-FBBDF8338C25 | C20: ='Components Data Source'!C20 -> Base2dObject.fcpx | D20: ='Components Data Source'!D20 -> Components\IO_Source\2dGDI\Base2dObject.fcfx | E20: ='Components Data Source'!E20 -> FREE | F20: ='Components Data Source'!F20 -> DEVELOPMENT | G20: ='Components Data Source'!G20 -> 0 | H20: ='Components Data Source'!H20 -> 0 | ... L20: ='Components Data Source'!L20 -> 1 | M20: N | N20: =HYPERLINK('Components Data Source'!M20) -> https://www.flowcode.co.uk/wiki/index.php?title=Component:_ID_e11146d4_2d40_4be6_95cc_fbbdf8338c25 | O20: A | Q20: =IF(L20=1,IF(K20=1,"",1),"") | R20: N | V20: Select | W20: Select | Z20: =IF(AND(R20="Y",Y20="Y"),1,IF(R20="N",2,IF(R20="",4,IF(Y20="A",3,0)))) -> 2 | AD20: A | AF20: A | AG20: A | AI20: =VLOOKUP(B20,'Components Usage'!A$2:C$603,3,FALSE) -> 3
A21: ='Components Data Source'!A21 -> Base2dStatic | B21: ='Components Data Source'!B21 -> 6E425786-81B6-4F40-AC24-6C674BFFE958 | C21: ='Components Data Source'!C21 -> Base2dStatic.fcpx | D21: ='Components Data Source'!D21 -> Components\IO_Source\2dGDI\Base2dStatic.fcfx | E21: ='Components Data Source'!E21 -> FREE | F21: ='Components Data Source'!F21 -> DEVELOPMENT | G21: ='Components Data Source'!G21 -> 0 | H21: ='Components Data Source'!H21 -> 0 | ... L21: ='Components Data Source'!L21 -> 1 | M21: N | N21: =HYPERLINK('Components Data Source'!M21) -> https://www.flowcode.co.uk/wiki/index.php?title=Component:_ID_6e425786_81b6_4f40_ac24_6c674bffe958 | O21: A | Q21: =IF(L21=1,IF(K21=1,"",1),"") | R21: N | V21: Select | W21: Select | Z21: =IF(AND(R21="Y",Y21="Y"),1,IF(R21="N",2,IF(R21="",4,IF(Y21="A",3,0)))) -> 2 | AD21: A | AF21: A | AG21: A | AI21: =VLOOKUP(B21,'Components Usage'!A$2:C$603,3,FALSE) -> 3
A22: ='Components Data Source'!A22 -> Base 64 | B22: ='Components Data Source'!B22 -> A78483E1-B293-47E7-984C-55984FC93571 | C22: ='Components Data Source'!C22 -> Base64.fcpx | D22: ='Components Data Source'!D22 -> Components\IO_Source\Storage\Base64.fcfx | E22: ='Components Data Source'!E22 -> COMMSC | F22: ='Components Data Source'!F22 -> STORAGE | G22: ='Components Data Source'!G22 -> STORAGE | H22: ='Components Data Source'!H22 -> 0 | ... L22: ='Components Data Source'!L22 -> 1 | M22: N | N22: =HYPERLINK('Components Data Source'!M22) -> https://www.flowcode.co.uk/wiki/index.php?title=Component:_ID_a78483e1_b293_47e7_984c_55984fc93571 | O22: Y | Q22: =IF(L22=1,IF(K22=1,"",1),"") | R22: Y | S22: Y | T22: N | U22: Y | V22: None | W22: NetComms | X22: Y | Y22: Y | Z22: =IF(AND(R22="Y",Y22="Y"),1,IF(R22="N",2,IF(R22="",4,IF(Y22="A",3,0)))) -> 1 | AD22: Y | AE22: Y | AF22: A | AG22: Y | AI22: =VLOOKUP(B22,'Components Usage'!A$2:C$603,3,FALSE) -> 2 | AJ22: A
A23: ='Components Data Source'!A23 -> GLCD Base | B23: ='Components Data Source'!B23 -> 4384CBA9-0BEA-4359-8C5B-DCD046AA7778 | C23: ='Components Data Source'!C23 -> Base_GLCD.fcpx | D23: ='Components Data Source'!D23 -> Components\IO_Source\displays\glcd_base.fcfx | E23: ='Components Data Source'!E23 -> FREE | F23: ='Components Data Source'!F23 -> GRAPHICAL | G23: ='Components Data Source'!G23 -> 0 | H23: ='Components Data Source'!H23 -> 0 | ... L23: ='Components Data Source'!L23 -> 1 | M23: N | N23: =HYPERLINK('Components Data Source'!M23) -> https://www.flowcode.co.uk/wiki/index.php?title=Component:_ID_4384cba9_0bea_4359_8c5b_dcd046aa7778 | O23: A | Q23: =IF(L23=1,IF(K23=1,"",1),"") | R23: N | V23: Select | W23: Select | Z23: =IF(AND(R23="Y",Y23="Y"),1,IF(R23="N",2,IF(R23="",4,IF(Y23="A",3,0)))) -> 2 | AD23: A | AF23: A | AG23: Y | AI23: =VLOOKUP(B23,'Components Usage'!A$2:C$603,3,FALSE) -> 10
A24: ='Components Data Source'!A24 -> Basic IO Shield PCB | B24: ='Components Data Source'!B24 -> 0CC9193A-1F8B-4D22-85D0-952B37C40B25 | C24: ='Components Data Source'!C24 -> BasicIOShieldPCB.fcpx | D24: ='Components Data Source'!D24 -> Components\IO_Source\PCBs\BasicIOShieldPCBCompSource.fcfx | E24: ='Components Data Source'!E24 -> FREE | F24: ='Components Data Source'!F24 -> MISC | G24: ='Components Data Source'!G24 -> 0 | H24: ='Components Data Source'!H24 -> 0 | ... L24: ='Components Data Source'!L24 -> 0 | M24: N | N24: =HYPERLINK('Components Data Source'!M24) -> https://www.flowcode.co.uk/wiki/index.php?title=Component:_ID_0cc9193a_1f8b_4d22_85d0_952b37c40b25 | O24: A | Q24: =IF(L24=1,IF(K24=1,"",1),"") | R24: N | V24: Select | W24: Select | Z24: =IF(AND(R24="Y",Y24="Y"),1,IF(R24="N",2,IF(R24="",4,IF(Y24="A",3,0)))) -> 2 | AD24: A | AI24: =VLOOKUP(B24,'Components Usage'!A$2:C$603,3,FALSE) -> 0
A25: ='Components Data Source'!A25 -> Bevel | B25: ='Components Data Source'!B25 -> B71C1512-A4C6-4887-A443-1ECF08D14D64 | C25: ='Components Data Source'!C25 -> Bevel2d.fcpx | D25: ='Components Data Source'!D25 -> Components\IO_Source\2dGDI\bevel2d.fcfx | E25: ='Components Data Source'!E25 -> FREE | F25: ='Components Data Source'!F25 -> 2D SHAPES | G25: ='Components Data Source'!G25 -> 0 | H25: ='Components Data Source'!H25 -> 0 | ... L25: ='Components Data Source'!L25 -> 1 | M25: N | N25: =HYPERLINK('Components Data Source'!M25) -> https://www.flowcode.co.uk/wiki/index.php?title=Component:_ID_b71c1512_a4c6_4887_a443_1ecf08d14d64 | O25: A | Q25: =IF(L25=1,IF(K25=1,"",1),"") | R25: N | V25: Select | W25: Select | Z25: =IF(AND(R25="Y",Y25="Y"),1,IF(R25="N",2,IF(R25="",4,IF(Y25="A",3,0)))) -> 2 | AD25: A | AF25: A | AG25: A | AI25: =VLOOKUP(B25,'Components Usage'!A$2:C$603,3,FALSE) -> 0
A26: ='Components Data Source'!A26 -> GLCD Bitmap Drawer ROM | B26: ='Components Data Source'!B26 -> 52DD90BD-FEC9-4EE5-934C-E4B2297168A5 | C26: ='Components Data Source'!C26 -> BitmapDrawer.fcpx | D26: ='Components Data Source'!D26 -> Components\IO_Source\displays\GLCD_Draw_Bitmap.fcfx | E26: ='Components Data Source'!E26 -> DISPLAYS | F26: ='Components Data Source'!F26 -> GRAPHICAL LIBRARY | G26: ='Components Data Source'!G26 -> 0 | H26: ='Components Data Source'!H26 -> 0 | ... L26: ='Components Data Source'!L26 -> 0 | M26: N | N26: =HYPERLINK('Components Data Source'!M26) -> https://www.flowcode.co.uk/wiki/index.php?title=Component:_ID_52dd90bd_fec9_4ee5_934c_e4b2297168a5 | O26: Y | Q26: =IF(L26=1,IF(K26=1,"",1),"") | R26: Y | S26: Y | T26: N | U26: Y | V26: None | W26: GLCD | X26: Y | Y26: Y | Z26: =IF(AND(R26="Y",Y26="Y"),1,IF(R26="N",2,IF(R26="",4,IF(Y26="A",3,0)))) -> 1 | AD26: Y | AE26: Y | AF26: A | AG26: Y | AI26: =VLOOKUP(B26,'Components Usage'!A$2:C$603,3,FALSE) -> 24 | AJ26: A
A27: ='Components Data Source'!A27 -> GLCD Bitmap Drawer FAT | B27: ='Components Data Source'!B27 -> B02B7C75-53CB-4BE4-871F-61BE633D898C | C27: ='Components Data Source'!C27 -> BitmapDrawerFAT.fcpx | D27: ='Components Data Source'!D27 -> Components\IO_Source\displays\GLCD_Draw_Bitmap_FAT.fcfx | E27: ='Components Data Source'!E27 -> STORAGE | F27: ='Components Data Source'!F27 -> GRAPHICAL LIBRARY | G27: ='Components Data Source'!G27 -> 0 | H27: ='Components Data Source'!H27 -> 0 | ... L27: ='Components Data Source'!L27 -> 0 | M27: N | N27: =HYPERLINK('Components Data Source'!M27) -> https://www.flowcode.co.uk/wiki/index.php?title=Component:_ID_b02b7c75_53cb_4be4_871f_61be633d898c | O27: Y | Q27: =IF(L27=1,IF(K27=1,"",1),"") | R27: Y | S27: Y | T27: N | U27: Y | V27: None | W27: File | X27: Y | Y27: Y | Z27: =IF(AND(R27="Y",Y27="Y"),1,IF(R27="N",2,IF(R27="",4,IF(Y27="A",3,0)))) -> 1 | AD27: Y | AE27: Y | AF27: A | AG27: Y | AI27: =VLOOKUP(B27,'Components Usage'!A$2:C$603,3,FALSE) -> 8 | AJ27: A
A28: ='Components Data Source'!A28 -> Bluetooth v2 (EB024 Generic AT) | B28: ='Components Data Source'!B28 -> 76B3EB5C-2D23-4C8D-BDE8-505032BC886A | C28: ='Components Data Source'!C28 -> Bluetooth2.fcpx | D28: ='Components Data Source'!D28 -> Components\IO_Source\Bluetooth_V2.fcfx | E28: ='Components Data Source'!E28 -> COMMSB | F28: ='Components Data Source'!F28 -> WIRELESS | G28: ='Components Data Source'!G28 -> 0 | H28: ='Components Data Source'!H28 -> 0 | ... L28: ='Components Data Source'!L28 -> 0 | M28: N | N28: =HYPERLINK('Components Data Source'!M28) -> https://www.flowcode.co.uk/wiki/index.php?title=Component:_ID_76b3eb5c_2d23_4c8d_bde8_505032bc886a | O28: Y | Q28: =IF(L28=1,IF(K28=1,"",1),"") | R28: Y | S28: Y | T28: Y | U28: Y | V28: None | W28: UART | X28: Y | Y28: Y | Z28: =IF(AND(R28="Y",Y28="Y"),1,IF(R28="N",2,IF(R28="",4,IF(Y28="A",3,0)))) -> 1 | AB28: Changed injector ref within properties to API 15/6/21 | AD28: Y | AE28: Y | AF28: A | AG28: Y | AI28: =VLOOKUP(B28,'Components Usage'!A$2:C$603,3,FALSE) -> 0 | AJ28: A
A29: ='Components Data Source'!A29 -> Bluetooth(BL0170) | B29: ='Components Data Source'!B29 -> 5F9D5A58-6C01-4588-AFA0-DF4C01CE161A | C29: ='Components Data Source'!C29 -> BluetoothBL0170.fcpx | D29: ='Components Data Source'!D29 -> Components\IO_Source\EB2\EBlocks2_Bluetooth_RN4677_BL0170.fcfx | E29: ='Components Data Source'!E29 -> COMMSB | F29: ='Components Data Source'!F29 -> E-BLOCKS 2 | G29: ='Components Data Source'!G29 -> 0 | H29: ='Components Data Source'!H29 -> 0 | ... L29: ='Components Data Source'!L29 -> 0 | M29: N | N29: =HYPERLINK('Components Data Source'!M29) -> https://www.flowcode.co.uk/wiki/index.php?title=Component:_ID_5f9d5a58_6c01_4588_afa0_df4c01ce161a | O29: O | Q29: =IF(L29=1,IF(K29=1,"",1),"") | R29: Y | S29: Y | T29: Y | U29: Y | V29: None | W29: UART | X29: Y | Y29: Y | Z29: =IF(AND(R29="Y",Y29="Y"),1,IF(R29="N",2,IF(R29="",4,IF(Y29="A",3,0)))) -> 1 | AD29: Y | AE29: N | AF29: A | AG29: N | AI29: =VLOOKUP(B29,'Components Usage'!A$2:C$603,3,FALSE) -> 2 | AJ29: A
A30: ='Components Data Source'!A30 -> Bluetooth(RN4677) | B30: ='Components Data Source'!B30 -> 0C7DF3FC-A46F-4712-8CD3-77079978F4FC | C30: ='Components Data Source'!C30 -> BluetoothRN4677.fcpx | D30: ='Components Data Source'!D30 -> Components\IO_Source\Bluetooth_RN4677.fcfx | E30: ='Components Data Source'!E30 -> COMMSB | F30: ='Components Data Source'!F30 -> WIRELESS | G30: ='Components Data Source'!G30 -> 0 | H30: ='Components Data Source'!H30 -> 0 | ... L30: ='Components Data Source'!L30 -> 0 | M30: N | N30: =HYPERLINK('Components Data Source'!M30) -> https://www.flowcode.co.uk/wiki/index.php?title=Component:_ID_0c7df3fc_a46f_4712_8cd3_77079978f4fc | O30: Y | Q30: =IF(L30=1,IF(K30=1,"",1),"") | R30: Y | S30: Y | T30: Y | U30: Y | V30: None | W30: UART | X30: Y | Y30: Y | Z30: =IF(AND(R30="Y",Y30="Y"),1,IF(R30="N",2,IF(R30="",4,IF(Y30="A",3,0)))) -> 1 | AD30: Y | AE30: N | AF30: A | AG30: N | AI30: =VLOOKUP(B30,'Components Usage'!A$2:C$603,3,FALSE) -> 4 | AJ30: A
A31: ='Components Data Source'!A31 -> Bluetooth (HC05 / HC06) | B31: ='Components Data Source'!B31 -> A8DBE015-0985-4581-ABD5-1CC44F576FAB | C31: ='Components Data Source'!C31 -> Bluetooth_HC05.fcpx | D31: ='Components Data Source'!D31 -> Components\IO_Source\BTHC05.fcfx | E31: ='Components Data Source'!E31 -> COMMSB | F31: ='Components Data Source'!F31 -> WIRELESS | G31: ='Components Data Source'!G31 -> 0 | H31: ='Components Data Source'!H31 -> 0 | ... L31: ='Components Data Source'!L31 -> 0 | M31: N | N31: =HYPERLINK('Components Data Source'!M31) -> https://www.flowcode.co.uk/wiki/index.php?title=Component:_ID_a8dbe015_0985_4581_abd5_1cc44f576fab | O31: Y | P31: File | Q31: =IF(L31=1,IF(K31=1,"",1),"") | R31: Y | S31: Y | T31: Y | V31: None | W31: UART | X31: Y | Y31: Y | Z31: =IF(AND(R31="Y",Y31="Y"),1,IF(R31="N",2,IF(R31="",4,IF(Y31="A",3,0)))) -> 1 | AB31: Changed injector ref within properties to API 15/6/21 | AD31: Y | AE31: Y | AF31: N | AG31: Y | AI31: =VLOOKUP(B31,'Components Usage'!A$2:C$603,3,FALSE) -> 10 | AJ31: A
A32: ='Components Data Source'!A32 -> Bluetooth (ESP32 SPP) | B32: ='Components Data Source'!B32 -> 8BE2CE64-4860-468A-AA8A-EAC443274DA3 | C32: ='Components Data Source'!C32 -> Bluetooth_SPP_ESP32.fcpx | D32: ='Components Data Source'!D32 -> Components\IO_Source\Bluetooth_ESP32_SPP.fcfx | E32: ='Components Data Source'!E32 -> FREE | F32: ='Components Data Source'!F32 -> WIRELESS | G32: ='Components Data Source'!G32 -> 0 | H32: ='Components Data Source'!H32 -> 0 | ... L32: ='Components Data Source'!L32 -> 0 | M32: N | N32: =HYPERLINK('Components Data Source'!M32) -> https://www.flowcode.co.uk/wiki/index.php?title=Component:_ID_8be2ce64_4860_468a_aa8a_eac443274da3 | O32: Y | Q32: =IF(L32=1,IF(K32=1,"",1),"") | R32: Y | S32: Y | T32: Y | U32: Y | V32: None | W32: None | X32: Y | Y32: ? | Z32: =IF(AND(R32="Y",Y32="Y"),1,IF(R32="N",2,IF(R32="",4,IF(Y32="A",3,0)))) -> 0 | AA32: Y | AB32: No indicators were used. Is that correct? | AD32: Y | AE32: N | AF32: A | AG32: Y | AI32: =VLOOKUP(B32,'Components Usage'!A$2:C$603,3,FALSE) -> 27 | AJ32: A
A33: ='Components Data Source'!A33 -> Brushless Motor (Standard) | B33: ='Components Data Source'!B33 -> DC99E179-216F-4618-AEE7-3F5F87541A9D | C33: ='Components Data Source'!C33 -> BrushlessMotor.fcpx | D33: ='Components Data Source'!D33 -> Components\IO_Source\mechatronics\BrushlessMotor.fcfx | E33: ='Components Data Source'!E33 -> MECHATRONICS | F33: ='Components Data Source'!F33 -> 0 | G33: ='Components Data Source'!G33 -> 0 | H33: ='Components Data Source'!H33 -> 0 | ... L33: ='Components Data Source'!L33 -> 0 | M33: N | N33: =HYPERLINK('Components Data Source'!M33) -> https://www.flowcode.co.uk/wiki/index.php?title=Component:_ID_dc99e179_216f_4618_aee7_3f5f87541a9d | O33: Y | P33: Confusing . Why examples for keypad? | Q33: =IF(L33=1,IF(K33=1,"",1),"") | R33: N | V33: Select | W33: Select | Z33: =IF(AND(R33="Y",Y33="Y"),1,IF(R33="N",2,IF(R33="",4,IF(Y33="A",3,0)))) -> 2 | AD33: N | AF33: N | AG33: N | AI33: =VLOOKUP(B33,'Components Usage'!A$2:C$603,3,FALSE) -> 3
A34: ='Components Data Source'!A34 -> Bubble Chart | B34: ='Components Data Source'!B34 -> 5D52E8A2-F248-4318-A0AC-E7B9503237CF | C34: ='Components Data Source'!C34 -> BubbleChart.fcpx | D34: ='Components Data Source'!D34 -> Components\IO_Source\2dGDI\ChartBubble.fcfx | E34: ='Components Data Source'!E34 -> FREE | F34: ='Components Data Source'!F34 -> CHARTS | G34: ='Components Data Source'!G34 -> CHARTS | H34: ='Components Data Source'!H34 -> 0 | ... L34: ='Components Data Source'!L34 -> 1 | M34: N | N34: =HYPERLINK('Components Data Source'!M34) -> https://www.flowcode.co.uk/wiki/index.php?title=Component:_ID_5d52e8a2_f248_4318_a0ac_e7b9503237cf | O34: Y | Q34: =IF(L34=1,IF(K34=1,"",1),"") | R34: N | V34: Select | W34: Select | Z34: =IF(AND(R34="Y",Y34="Y"),1,IF(R34="N",2,IF(R34="",4,IF(Y34="A",3,0)))) -> 2 | AD34: N | AF34: N | AG34: N | AI34: =VLOOKUP(B34,'Components Usage'!A$2:C$603,3,FALSE) -> 0
A35: ='Components Data Source'!A35 -> Buzzer | B35: ='Components Data Source'!B35 -> 04BBD3B8-EE11-40EB-91E8-1BBBD6F65B8C | C35: ='Components Data Source'!C35 -> Buzzer.fcpx | D35: ='Components Data Source'!D35 -> Components\IO_Source\outputs\Buzzer.fcfx | E35: ='Components Data Source'!E35 -> BASICIO | F35: ='Components Data Source'!F35 -> AUDIO OUTPUT | G35: ='Components Data Source'!G35 -> 0 | H35: ='Components Data Source'!H35 -> 0 | ... L35: ='Components Data Source'!L35 -> 0 | M35: N | N35: =HYPERLINK('Components Data Source'!M35) -> https://www.flowcode.co.uk/wiki/index.php?title=Component:_ID_04bbd3b8_ee11_40eb_91e8_1bbbd6f65b8c | O35: Y | Q35: =IF(L35=1,IF(K35=1,"",1),"") | R35: Y | S35: Y | T35: N | U35: N | V35: None | W35: None | X35: Y | Y35: Y | Z35: =IF(AND(R35="Y",Y35="Y"),1,IF(R35="N",2,IF(R35="",4,IF(Y35="A",3,0)))) -> 1 | AD35: Y | AE35: N | AF35: Y | AG35: Y | AI35: =VLOOKUP(B35,'Components Usage'!A$2:C$603,3,FALSE) -> 79 | AJ35: Y
A36: ='Components Data Source'!A36 -> CAN (Internal MCP2515) | B36: ='Components Data Source'!B36 -> DA332928-6342-4C2C-AFC7-EAF33917D33E | C36: ='Components Data Source'!C36 -> CAN.fcpx | D36: ='Components Data Source'!D36 -> Components\IO_Source\CAN.fcfx | E36: ='Components Data Source'!E36 -> COMMSA | F36: ='Components Data Source'!F36 -> COMMS: INTERFACE | G36: ='Components Data Source'!G36 -> COMMS: INTERFACE | H36: ='Components Data Source'!H36 -> 0 | ... L36: ='Components Data Source'!L36 -> 1 | M36: N | N36: =HYPERLINK('Components Data Source'!M36) -> https://www.flowcode.co.uk/wiki/index.php?title=Component:_ID_da332928_6342_4c2c_afc7_eaf33917d33e | O36: Y | Q36: =IF(L36=1,IF(K36=1,"",1),"") | R36: Y | S36: Y | T36: Y | U36: Y | V36: None | W36: SPI | X36: Y | Y36: Y | Z36: =IF(AND(R36="Y",Y36="Y"),1,IF(R36="N",2,IF(R36="",4,IF(Y36="A",3,0)))) -> 1 | AD36: Y | AE36: Y | AF36: Y | AG36: Y | AI36: =VLOOKUP(B36,'Components Usage'!A$2:C$603,3,FALSE) -> 67 | AJ36: A
A37: ='Components Data Source'!A37 -> CNC Machine | B37: ='Components Data Source'!B37 -> 93252F96-A8E5-4D65-8C40-11614BB15B52 | C37: ='Components Data Source'!C37 -> CNCMachine.fcpx | D37: ='Components Data Source'!D37 -> Components\IO_Source\mechatronics\Electro Mechanical\CNC Source Files\CNCComponent_v002.fcfx | E37: ='Components Data Source'!E37 -> MODELS | F37: ='Components Data Source'!F37 -> SCENARIOS | G37: ='Components Data Source'!G37 -> 0 | H37: ='Components Data Source'!H37 -> 0 | ... L37: ='Components Data Source'!L37 -> 0 | M37: N | N37: =HYPERLINK('Components Data Source'!M37) -> https://www.flowcode.co.uk/wiki/index.php?title=Component:_ID_93252f96_a8e5_4d65_8c40_11614bb15b52 | O37: Y | Q37: =IF(L37=1,IF(K37=1,"",1),"") | R37: N | V37: Select | W37: Select | Z37: =IF(AND(R37="Y",Y37="Y"),1,IF(R37="N",2,IF(R37="",4,IF(Y37="A",3,0)))) -> 2 | AD37: Y | AE37: Y | AF37: A | AG37: Link to a worksheet | AI37: =VLOOKUP(B37,'Components Usage'!A$2:C$603,3,FALSE) -> 3 | AJ37: A
A38: ='Components Data Source'!A38 -> COM Port | B38: ='Components Data Source'!B38 -> CBB3C28E-2D73-4442-AC52-23A3B45D9870 | C38: ='Components Data Source'!C38 -> COMPort.fcpx | D38: ='Components Data Source'!D38 -> Components\IO_Source\Serial_DLL.fcfx | E38: ='Components Data Source'!E38 -> FREE | F38: ='Components Data Source'!F38 -> RUNTIME TOOLS | G38: ='Components Data Source'!G38 -> COMMS: INTERFACE | H38: ='Components Data Source'!H38 -> 0 | ... L38: ='Components Data Source'!L38 -> 1 | M38: N | N38: =HYPERLINK('Components Data Source'!M38) -> https://www.flowcode.co.uk/wiki/index.php?title=Component:_ID_cbb3c28e_2d73_4442_ac52_23a3b45d9870 | O38: Y | Q38: =IF(L38=1,IF(K38=1,"",1),"") | R38: Y | S38: Y | T38: Y | U38: Y | V38: None | W38: None | X38: Y | Y38: Y | Z38: =IF(AND(R38="Y",Y38="Y"),1,IF(R38="N",2,IF(R38="",4,IF(Y38="A",3,0)))) -> 1 | AD38: Y | AE38: Y | AF38: A | AG38: Y | AI38: =VLOOKUP(B38,'Components Usage'!A$2:C$603,3,FALSE) -> 39 | AJ38: Y
A39: ='Components Data Source'!A39 -> CSV Read/Write | B39: ='Components Data Source'!B39 -> 7D0C33A1-0AAA-4250-84BB-F96FC113ABAC | C39: ='Components Data Source'!C39 -> CSV_Writer.fcpx | D39: ='Components Data Source'!D39 -> Components\IO_Source\SCADA\CSV_Writer.fcfx | E39: ='Components Data Source'!E39 -> FREE | F39: ='Components Data Source'!F39 -> RUNTIME TOOLS | G39: ='Components Data Source'!G39 -> STORAGE | H39: ='Components Data Source'!H39 -> 0 | ... L39: ='Components Data Source'!L39 -> 1 | M39: N | N39: =HYPERLINK('Components Data Source'!M39) -> https://www.flowcode.co.uk/wiki/index.php?title=Component:_ID_7d0c33a1_0aaa_4250_84bb_f96fc113abac | O39: Y | Q39: =IF(L39=1,IF(K39=1,"",1),"") | R39: Y | S39: Y | T39: N | U39: Y | V39: None | W39: None | X39: Y | Y39: Y | Z39: =IF(AND(R39="Y",Y39="Y"),1,IF(R39="N",2,IF(R39="",4,IF(Y39="A",3,0)))) -> 1 | AD39: Y | AE39: Y | AF39: A | AG39: Y | AI39: =VLOOKUP(B39,'Components Usage'!A$2:C$603,3,FALSE) -> 15 | AJ39: A
A40: ='Components Data Source'!A40 -> Car Seat | B40: ='Components Data Source'!B40 -> FDE30DE0-35ED-40CA-937A-88DA6409C1D2 | C40: ='Components Data Source'!C40 -> CarSeat.fcpx | D40: ='Components Data Source'!D40 -> Components\IO_Source\mechatronics\Electro Mechanical\Car Seat Source Files\CarSeatSource_v004.fcfx | E40: ='Components Data Source'!E40 -> MODELS | F40: ='Components Data Source'!F40 -> SCENARIOS | G40: ='Components Data Source'!G40 -> 0 | H40: ='Components Data Source'!H40 -> 0 | ... L40: ='Components Data Source'!L40 -> 0 | M40: N | N40: =HYPERLINK('Components Data Source'!M40) -> https://www.flowcode.co.uk/wiki/index.php?title=Component:_ID_fde30de0_35ed_40ca_937a_88da6409c1d2 | O40: Y | Q40: =IF(L40=1,IF(K40=1,"",1),"") | R40: N | V40: Select | W40: Select | Z40: =IF(AND(R40="Y",Y40="Y"),1,IF(R40="N",2,IF(R40="",4,IF(Y40="A",3,0)))) -> 2 | AD40: Y | AE40: Y | AF40: N | AG40: Y | AI40: =VLOOKUP(B40,'Components Usage'!A$2:C$603,3,FALSE) -> 1 | AJ40: A
...

Sheet Components Usage
A1: GUID | B1: Name | C1: usage
A2: 7FDAEC78-394E-4EC9-A578-4F1A12A12076 | B2: LED (5mm Panel) | C2: 486
A3: C73616D1-7AD0-45D9-AADA-69CCFA4C5EFC | B3: UART (RS232) | C3: 443
A4: 63177601-E8E2-4330-89D3-A4C5A7E228F5 | B4: LED Array (PCB) | C4: 390
A5: 14683EA8-5A08-4B3A-BE2D-3DEA3E17E720 | B5: Potentiometer (Colour) | C5: 309
A6: 5C1DA48F-CE54-4622-BDD9-FC812E373696 | B6: Switch (Push Panel) | C6: 300
A7: D92E8259-F3A8-4176-A8C4-FE7CA42B2C3F | B7: LED (5mm PCB) | C7: 288
A8: 444FB704-814C-4707-A15C-759BA088505C | B8: PWM (Internal) | C8: 266
A9: 52C5383B-4F48-4029-8B75-C3633F7CF892 | B9: 7Segment (Single) | C9: 216
A10: 7A287A58-CBA5-42AD-B8A5-58694D7F678A | B10: Switch (Slide PCB) | C10: 216
A11: 24219805-113D-4B12-B6BD-E1B0B0C33981 | B11: I2C Master | C11: 181
A12: DCBF571F-A6FA-402D-BDD4-BE00CCA4070F | B12: EEPROM | C12: 171
A13: 1A8C2BB7-8BED-4A1C-9186-BA24688C8840 | B13: Potentiometer (Slider) | C13: 169
... A603: F54FA744-5AF4-4C08-BDB9-FB31848A2B63 | B603: XML JSON Parser | C603: 0

Sheet Component Testing
A1: GUID | B1: Component | C1: Component Macro tested | D1: BL0011 Pass? | E1: ESP32 Pass | F1: RedBoard. Pass? | G1: ARM | H1: Notes
A2: C73616D1-7AD0-45D9-AADA-69CCFA4C5EFC | B2: UART | C2: SendChar (57600 Baud) | D2: Y | E2: Y | F2: Y | G2: N (Y Fixed) | H2: RX interrupt used and much be first. Error H = 2.6%, L = 2.4%. Uart does not work at all on Arm
A3: C73616D1-7AD0-45D9-AADA-69CCFA4C5EFC | B3: UART | C3: ReceiveChar (57600 Baud) | D3: Y | E3: Y | F3: Y | G3: N (Y Fixed)
A4: C73616D1-7AD0-45D9-AADA-69CCFA4C5EFC | B4: UART | C4: SendSting (9600,57600 & 115200 Baud) | D4: Y | E4: Y | F4: Y | G4: N (Y Fixed)
A5: C73616D1-7AD0-45D9-AADA-69CCFA4C5EFC | B5: UART | C5: ReceieveSting (115200 Baud) | D5: Y | E5: Y | F5: Y | G5: N (Y Fixed)
A6: C73616D1-7AD0-45D9-AADA-69CCFA4C5EFC | B6: UART | C6: ChangeHWBaud (9600,57600 & 115200 Baud) | D6: Y | E6: Y | F6: Y | G6: N (Y Fixed)
A7: C73616D1-7AD0-45D9-AADA-69CCFA4C5EFC | B7: UART | C7: SendFloat | D7: Y | E7: Y | F7: Y | G7: N (Y Fixed) | H7: Limited to 10 chars
A8: C73616D1-7AD0-45D9-AADA-69CCFA4C5EFC | B8: UART | C8: SendNumber | D8: Y | E8: Y | F8: Y | G8: N (Y Fixed)
A9: C73616D1-7AD0-45D9-AADA-69CCFA4C5EFC | B9: UART | C9: SendHexNumber | D9: Y | E9: Y | F9: Y | G9: N (Y Fixed)
A10: C73616D1-7AD0-45D9-AADA-69CCFA4C5EFC | B10: UART | C10: SendByteArray | D10: Y | E10: Y | F10: Y | G10: N (Y Fixed)
A11: C73616D1-7AD0-45D9-AADA-69CCFA4C5EFC | B11: UART | C11: SendBinary32Bit | D11: Y | E11: Y | F11: Y | G11: N (Y Fixed) | H11: Value sent 1023. Value on analyser MSB > LSB 0, 1,226 & 64.. Should have seen 0, 0, 3, 255
C12: Software mode ( Send "U") | D12: Y | E12: N | F12: N | G12: N (Y Fixed) | H12: BL0011 4% Error. ESP32 & RedBoard Teminiation error - won't compile
C13: Timer Version ( Send "U") | D13: Y | E13: N | F13: Y* | G13: N | H13: BL0061. Set timer 2 to 9600 UART at 14414 baud. Esp32 Not practicable as timer resolution is in ms only. *Works as indended, but will need to preload timer maco if standard Baud rates are required.
A15: 63177601-E8E2-4330-89D3-A4C5A7E228F5 | B15: LED Array | C15: BarGraph | D15: Y | E15: Y | F15: Y | G15: Y
A16: 63177601-E8E2-4330-89D3-A4C5A7E228F5 | B16: LED Array | C16: LEDOn | D16: Y | E16: Y | F16: Y | G16: Y
A17: 63177601-E8E2-4330-89D3-A4C5A7E228F5 | B17: LED Array | C17: AllOn | D17: Y | E17: Y | F17: Y | G17: Y
A18: 63177601-E8E2-4330-89D3-A4C5A7E228F5 | B18: LED Array | C18: LEDOff | D18: Y | E18: Y | F18: Y | G18: Y
A19: 63177601-E8E2-4330-89D3-A4C5A7E228F5 | B19: LED Array | C19: PointGraph | D19: Y | E19: Y | F19: Y | G19: Y
A20: 63177601-E8E2-4330-89D3-A4C5A7E228F5 | B20: LED Array | C20: WriteValue | D20: Y | E20: Y | F20: Y | G20: Y
A21: 63177601-E8E2-4330-89D3-A4C5A7E228F5 | B21: LED Array | C21: AllOff | D21: Y | E21: Y | F21: Y | G21: Y
A23: 14683EA8-5A08-4B3A-BE2D-3DEA3E17E720 | B23: Pot Colour | C23: RawAverageByte | D23: Y | E23: Y | F23: Y | G23: Y | H23: BL0011 A6 Not working with switch on XTAL postion
A24: 14683EA8-5A08-4B3A-BE2D-3DEA3E17E720 | B24: Pot Colour | C24: RawAverageInt | D24: Y | E24: Y | F24: Y | G24: Y
A25: 14683EA8-5A08-4B3A-BE2D-3DEA3E17E720 | B25: Pot Colour | C25: RawSampleInt | D25: Y | E25: Y | F25: Y | G25: Y | H25: BL0061 not stable no matter what PLCK is selected.
A26: 14683EA8-5A08-4B3A-BE2D-3DEA3E17E720 | B26: Pot Colour | C26: RawSampleByte | D26: Y | E26: Y | F26: Y | G26: Y
A27: 14683EA8-5A08-4B3A-BE2D-3DEA3E17E720 | B27: Pot Colour | C27: GetString | D27: Y | E27: Y | F27: Y | G27: Y
A28: 14683EA8-5A08-4B3A-BE2D-3DEA3E17E720 | B28: Pot Colour | C28: GetByte | D28: Y | E28: Y | F28: Y | G28: Y
A29: 14683EA8-5A08-4B3A-BE2D-3DEA3E17E720 | B29: Pot Colour | C29: GetInt | D29: Y | E29: Y | F29: Y | G29: Y
A30: 14683EA8-5A08-4B3A-BE2D-3DEA3E17E720 | B30: Pot Colour | C30: GetVoltage | D30: Y | E30: Y | F30: Y | G30: Y
A31: 14683EA8-5A08-4B3A-BE2D-3DEA3E17E720 | B31: Pot Colour | C31: GetAverageByte | D31: Y | E31: Y | F31: Y | G31: Y
A32: 14683EA8-5A08-4B3A-BE2D-3DEA3E17E720 | B32: Pot Colour | C32: GetAverageInt | D32: Y | E32: Y | F32: Y | G32: Y
A33: 14683EA8-5A08-4B3A-BE2D-3DEA3E17E720 | B33: Pot Colour | C33: Ref+ | D33: Y | E33: N (Y Fixed) | F33: Y | G33: Y | H33: BL0061 Unable to assign Vref+ to a pin as its connected to VDD via a coil. ESP32 Vref should be about 1.1V. There is no difference to selcted VDD (Fixed).
C34: FVR | D34: Y | E34: N/A | F34: Y | H34: BL0011 No mention of FVR wihtin Tooltips. Redboard Vref option tooltips mentions Vref+ Pin When its AREF. ESP change tooltips from Vref+ pin to internal 1V
A36: 444fb704-814c-4707-a15c-759ba088505c | B36: PWM (Internal) | C36: SetDutyCycle
A37: 444fb704-814c-4707-a15c-759ba088505c | B37: PWM (Internal) | C37: SetDutyCycle10Bit | H37: Bl0061. in the ball park. 1500Hz was 1125Hz
A38: 444fb704-814c-4707-a15c-759ba088505c | B38: PWM (Internal) | C38: Set Frequency | G38: N | H38: BL0061 Set frequency produces 100% duty. All devices. Does not simulate.
A39: 444fb704-814c-4707-a15c-759ba088505c | B39: PWM (Internal) | C39: ChangePeriod | H39: Change peroid 19999,16 is 150Hz, was expecting 200Hz
A41: f4400e36-dd95-4472-86da-4bba68d68d5d | B41: Quad 7seg | C41: ShowDigit | D41: Y | G41: Y | H41: I have noticed that seg A dimly flashes on random occasions when multiplexing.
A42: f4400e36-dd95-4472-86da-4bba68d68d5d | B42: Quad 7seg | C42: ShowSegments | D42: Y | G42: Y
A43: 52c5383b-4f48-4029-8b75-c3633f7cf892 | B43: 7seg | C43: ShowDigit | D43: Y | G43: Y
A44: 52c5383b-4f48-4029-8b75-c3633f7cf893 | B44: 7seg | C44: ShowSegments | D44: Y | G44: Y | H44: I have noticed that seg A dimly flashes on random occasions when multiplexing.
...

Sheet Components Data Source
A1: Name | B1: GUID | C1: FCPX Name | D1: Source | E1: ComponentPack | F1: Cat0 | G1: Cat1 | H1: Cat2 | I1: Peripherals | J1: Dynamic | K1: Embedded | L1: AppDeveloper | M1: URL
A2: DAC (AD5662) | B2: 3D87FFE9-97C1-4013-A2CD-82C24D0CCB48 | C2: ADC_AD5662.fcpx | D2: Components\IO_Source\outputs\DAC_AD5662.fcfx | E2: COMMSA | F2: ANALOG OUTPUT | I2: SPI | J2: 1 | K2: 1 | L2: 0 | M2: https://www.flowcode.co.uk/wiki/index.php?title=Component:_ID_3d87ffe9_97c1_4013_a2cd_82c24d0ccb48
A3: ADC (AD7680) | B3: 937E425E-21C0-4B08-8D8F-0BF80A6391D2 | C3: ADC_AD7680.fcpx | D3: Components\IO_Source\adc\ExternalADC_AD7680.fcfx | E3: COMMSA | F3: ANALOG INPUT | I3: SPI | J3: 1 | K3: 1 | L3: 0 | M3: https://www.flowcode.co.uk/wiki/index.php?title=Component:_ID_937e425e_21c0_4b08_8d8f_0bf80a6391d2
A4: DSP Audio Input (EB085) | B4: 87D8BAD5-6392-41FB-B370-D9B2C0F8F13F | C4: ADC_EB085.fcpx | D4: Components\IO_Source\adc\ExternalADC_AD7680_EB085.fcfx | E4: COMMSA | F4: E-BLOCKS 1 | I4: SPI | J4: 1 | K4: 1 | L4: 0 | M4: https://www.flowcode.co.uk/wiki/index.php?title=Component:_ID_87d8bad5_6392_41fb_b370_d9b2c0f8f13f
A5: ADC (MCP356X) | B5: 235FD689-BFD1-4C4A-A918-6C3C36E9A49F | C5: ADC_MCP356X.fcpx | D5: Components\IO_Source\adc\ExternalADC_MCP356X.fcfx | E5: FREE | F5: ANALOG INPUT | I5: SPI | J5: 1 | K5: 1 | L5: 0 | M5: https://www.flowcode.co.uk/wiki/index.php?title=Component:_ID_235fd689_bfd1_4c4a_a918_6c3c36e9a49f
A6: Infrared Array AMG88xx | B6: E1D52EFB-00D4-4E19-BA4C-29B292535EA1 | C6: AMG88xx.fcpx | D6: Components\IO_Source\Sensors\AMG88.fcfx | E6: SENSORS | F6: LIGHT | I6: I2C | J6: 1 | K6: 1 | L6: 1 | M6: https://www.flowcode.co.uk/wiki/index.php?title=Component:_ID_e1d52efb_00d4_4e19_ba4c_29b292535ea1
A7: Accelerometer(EB068) | B7: B81925B1-7504-4D77-AC90-3A4FA700FCC4 | C7: Accelerometer_EB068.fcpx | D7: Components\IO_Source\Sensors\Accelerometer_EB068.fcfx | E7: SENSORS | F7: E-BLOCKS 1 | I7: SPI I2C | J7: 1 | K7: 1 | L7: 0 | M7: https://www.flowcode.co.uk/wiki/index.php?title=Component:_ID_b81925b1_7504_4d77_ac90_3a4fa700fcc4
A8: Accelerometer 3-Axis(LIS3LV02DQ) | B8: 72F0A8C3-2B8F-4723-B22A-4A81873E5151 | C8: Accelerometer_LIS3LV02DQ.fcpx | D8: Components\IO_Source\Sensors\Accelerometer_LIS3LV0DQ.fcfx | E8: SENSORS | F8: MOVEMENT &AMP; ORIENTATION | I8: SPI I2C | J8: 1 | K8: 1 | L8: 1 | M8: https://www.flowcode.co.uk/wiki/index.php?title=Component:_ID_72f0a8c3_2b8f_4723_b22a_4a81873e5151
A9: Accelerometer 3-Axis(MMA8452Q) | B9: 2C716005-E9B5-46E3-86F9-30E5268341A9 | C9: Accelerometer_MMA8452Q.fcpx | D9: Components\IO_Source\Sensors\Accelerometer_MMA8452Q.fcfx | E9: SENSORS | F9: MOVEMENT &AMP; ORIENTATION | I9: SPI I2C | J9: 1 | K9: 1 | L9: 1 | M9: https://www.flowcode.co.uk/wiki/index.php?title=Component:_ID_2c716005_e9b5_46e3_86f9_30e5268341a9
A10: Ambient Light(BH1750FVI) | B10: E08872A7-6962-4B61-BCCA-71389F8ED8D7 | C10: AmbientLight.fcpx | D10: Components\IO_Source\Sensors\AmbientLight_BH1750FVI.fcfx | E10: SENSORS | F10: LIGHT | I10: I2C | J10: 1 | K10: 1 | L10: 0 | M10: https://www.flowcode.co.uk/wiki/index.php?title=Component:_ID_e08872a7_6962_4b61_bcca_71389f8ed8d7
A11: Area Chart | B11: A907D905-5879-48F3-9ADD-369A2F4E164F | C11: AreaChart.fcpx | D11: Components\IO_Source\2dGDI\ChartArea.fcfx | E11: FREE | F11: CHARTS | G11: CHARTS | J11: 1 | K11: 1 | L11: 1 | M11: https://www.flowcode.co.uk/wiki/index.php?title=Component:_ID_a907d905_5879_48f3_9add_369a2f4e164f
A12: Auto Version Identifier | B12: 1911D96C-78DD-414A-B23C-6691FB19F63F | C12: AutoVersionID.fcpx | D12: Components\IO_Source\AutoVersionID.fcfx | E12: STORAGE | F12: STORAGE | J12: 1 | K12: 1 | L12: 1 | M12: https://www.flowcode.co.uk/wiki/index.php?title=Component:_ID_1911d96c_78dd_414a_b23c_6691fb19f63f
A13: BBC News | B13: 72CD9559-26F7-4FFD-984C-CF3A82A6DB16 | C13: BBCNews.fcpx | D13: Components\IO_Source\IoT\BBCNews.fcfx | E13: COMMSC | F13: COMMS: IOT/CLOUD | J13: 1 | K13: 1 | L13: 1 | M13: https://www.flowcode.co.uk/wiki/index.php?title=Component:_ID_72cd9559_26f7_4ffd_984c_cf3a82a6db16
A14: BBC Weather Observation | B14: BF90426C-1763-4A7A-BE5C-B3E442E3F6D8 | C14: BBCWeather.fcpx | D14: Components\IO_Source\IoT\BBCWeatherObservation.fcfx | E14: COMMSC | F14: COMMS: IOT/CLOUD | J14: 1 | K14: 1 | L14: 1 | M14: https://www.flowcode.co.uk/wiki/index.php?title=Component:_ID_bf90426c_1763_4a7a_be5c_b3e442e3f6d8
A15: BBC Weather Forecast | B15: DF96FFA1-4D36-453A-8877-758F68A2676C | C15: BBCWeatherForecast.fcpx | D15: Components\IO_Source\IoT\BBCWeatherForecast.fcfx | E15: COMMSC | F15: COMMS: IOT/CLOUD | J15: 1 | K15: 1 | L15: 1 | M15: https://www.flowcode.co.uk/wiki/index.php?title=Component:_ID_df96ffa1_4d36_453a_8877_758f68a2676c
A16: Bar Chart | B16: 60B296CD-5B02-4C9C-9239-CCA36238F480 | C16: BarChart.fcpx | D16: Components\IO_Source\2dGDI\ChartBar.fcfx | E16: FREE | F16: CHARTS | G16: CHARTS | J16: 1 | K16: 1 | L16: 1 | M16: https://www.flowcode.co.uk/wiki/index.php?title=Component:_ID_60b296cd_5b02_4c9c_9239_cca36238f480
A17: Barometer (DPS310) | B17: CA60C1D2-FB77-4E3E-9D01-C4496D35DB1E | C17: Barometer_DPS310.fcpx | D17: Components\IO_Source\Sensors\Pressure_Sensor_DPS310.fcfx | E17: SENSORS | F17: ENVIRONMENTAL | I17: I2C | J17: 1 | K17: 1 | L17: 1 | M17: https://www.flowcode.co.uk/wiki/index.php?title=Component:_ID_ca60c1d2_fb77_4e3e_9d01_c4496d35db1e
A18: Base2dChart | B18: 1286CA5C-6453-4A92-9CCE-C6BA47457A69 | C18: Base2dChart.fcpx | D18: Components\IO_Source\2dGDI\Base2dChart.fcfx | E18: FREE | F18: DEVELOPMENT | J18: 1 | K18: 1 | L18: 1 | M18: https://www.flowcode.co.uk/wiki/index.php?title=Component:_ID_1286ca5c_6453_4a92_9cce_c6ba47457a69
A19: Base2dGauge | B19: B9285F96-06E8-4CDD-B0E2-A413F5150F1A | C19: Base2dGauge.fcpx | D19: Components\IO_Source\2dGDI\Base2dGauge.fcfx | E19: FREE | F19: DEVELOPMENT | J19: 1 | K19: 1 | L19: 1 | M19: https://www.flowcode.co.uk/wiki/index.php?title=Component:_ID_b9285f96_06e8_4cdd_b0e2_a413f5150f1a
A20: Base2dObject | B20: E11146D4-2D40-4BE6-95CC-FBBDF8338C25 | C20: Base2dObject.fcpx | D20: Components\IO_Source\2dGDI\Base2dObject.fcfx | E20: FREE | F20: DEVELOPMENT | J20: 1 | K20: 1 | L20: 1 | M20: https://www.flowcode.co.uk/wiki/index.php?title=Component:_ID_e11146d4_2d40_4be6_95cc_fbbdf8338c25
A21: Base2dStatic | B21: 6E425786-81B6-4F40-AC24-6C674BFFE958 | C21: Base2dStatic.fcpx | D21: Components\IO_Source\2dGDI\Base2dStatic.fcfx | E21: FREE | F21: DEVELOPMENT | J21: 1 | K21: 1 | L21: 1 | M21: https://www.flowcode.co.uk/wiki/index.php?title=Component:_ID_6e425786_81b6_4f40_ac24_6c674bffe958
A22: Base 64 | B22: A78483E1-B293-47E7-984C-55984FC93571 | C22: Base64.fcpx | D22: Components\IO_Source\Storage\Base64.fcfx | E22: COMMSC | F22: STORAGE | G22: STORAGE | J22: 1 | K22: 1 | L22: 1 | M22: https://www.flowcode.co.uk/wiki/index.php?title=Component:_ID_a78483e1_b293_47e7_984c_55984fc93571
A23: GLCD Base | B23: 4384CBA9-0BEA-4359-8C5B-DCD046AA7778 | C23: Base_GLCD.fcpx | D23: Components\IO_Source\displays\glcd_base.fcfx | E23: FREE | F23: GRAPHICAL | J23: 1 | K23: 1 | L23: 1 | M23: https://www.flowcode.co.uk/wiki/index.php?title=Component:_ID_4384cba9_0bea_4359_8c5b_dcd046aa7778
A24: Basic IO Shield PCB | B24: 0CC9193A-1F8B-4D22-85D0-952B37C40B25 | C24: BasicIOShieldPCB.fcpx | D24: Components\IO_Source\PCBs\BasicIOShieldPCBCompSource.fcfx | E24: FREE | F24: MISC | J24: 0 | M24: https://www.flowcode.co.uk/wiki/index.php?title=Component:_ID_0cc9193a_1f8b_4d22_85d0_952b37c40b25
A25: Bevel | B25: B71C1512-A4C6-4887-A443-1ECF08D14D64 | C25: Bevel2d.fcpx | D25: Components\IO_Source\2dGDI\bevel2d.fcfx | E25: FREE | F25: 2D SHAPES | J25: 1 | K25: 1 | L25: 1 | M25: https://www.flowcode.co.uk/wiki/index.php?title=Component:_ID_b71c1512_a4c6_4887_a443_1ecf08d14d64
A26: GLCD Bitmap Drawer ROM | B26: 52DD90BD-FEC9-4EE5-934C-E4B2297168A5 | C26: BitmapDrawer.fcpx | D26: Components\IO_Source\displays\GLCD_Draw_Bitmap.fcfx | E26: DISPLAYS | F26: GRAPHICAL LIBRARY | J26: 1 | K26: 1 | L26: 0 | M26: https://www.flowcode.co.uk/wiki/index.php?title=Component:_ID_52dd90bd_fec9_4ee5_934c_e4b2297168a5
A27: GLCD Bitmap Drawer FAT | B27: B02B7C75-53CB-4BE4-871F-61BE633D898C | C27: BitmapDrawerFAT.fcpx | D27: Components\IO_Source\displays\GLCD_Draw_Bitmap_FAT.fcfx | E27: STORAGE | F27: GRAPHICAL LIBRARY | J27: 1 | K27: 1 | L27: 0 | M27: https://www.flowcode.co.uk/wiki/index.php?title=Component:_ID_b02b7c75_53cb_4be4_871f_61be633d898c
A28: Bluetooth v2 (EB024 Generic AT) | B28: 76B3EB5C-2D23-4C8D-BDE8-505032BC886A | C28: Bluetooth2.fcpx | D28: Components\IO_Source\Bluetooth_V2.fcfx | E28: COMMSB | F28: WIRELESS | I28: UART | J28: 1 | K28: 1 | L28: 0 | M28: https://www.flowcode.co.uk/wiki/index.php?title=Component:_ID_76b3eb5c_2d23_4c8d_bde8_505032bc886a
A29: Bluetooth(BL0170) | B29: 5F9D5A58-6C01-4588-AFA0-DF4C01CE161A | C29: BluetoothBL0170.fcpx | D29: Components\IO_Source\EB2\EBlocks2_Bluetooth_RN4677_BL0170.fcfx | E29: COMMSB | F29: E-BLOCKS 2 | I29: UART | J29: 1 | K29: 1 | L29: 0 | M29: https://www.flowcode.co.uk/wiki/index.php?title=Component:_ID_5f9d5a58_6c01_4588_afa0_df4c01ce161a
A30: Bluetooth(RN4677) | B30: 0C7DF3FC-A46F-4712-8CD3-77079978F4FC | C30: BluetoothRN4677.fcpx | D30: Components\IO_Source\Bluetooth_RN4677.fcfx | E30: COMMSB | F30: WIRELESS | I30: UART | J30: 1 | K30: 1 | L30: 0 | M30: https://www.flowcode.co.uk/wiki/index.php?title=Component:_ID_0c7df3fc_a46f_4712_8cd3_77079978f4fc
A31: Bluetooth (HC05 / HC06) | B31: A8DBE015-0985-4581-ABD5-1CC44F576FAB | C31: Bluetooth_HC05.fcpx | D31: Components\IO_Source\BTHC05.fcfx | E31: COMMSB | F31: WIRELESS | I31: UART | J31: 1 | K31: 1 | L31: 0 | M31: https://www.flowcode.co.uk/wiki/index.php?title=Component:_ID_a8dbe015_0985_4581_abd5_1cc44f576fab
A32: Bluetooth (ESP32 SPP) | B32: 8BE2CE64-4860-468A-AA8A-EAC443274DA3 | C32: Bluetooth_SPP_ESP32.fcpx | D32: Components\IO_Source\Bluetooth_ESP32_SPP.fcfx | E32: FREE | F32: WIRELESS | J32: 1 | K32: 1 | L32: 0 | M32: https://www.flowcode.co.uk/wiki/index.php?title=Component:_ID_8be2ce64_4860_468a_aa8a_eac443274da3
A33: Brushless Motor (Standard) | B33: DC99E179-216F-4618-AEE7-3F5F87541A9D | C33: BrushlessMotor.fcpx | D33: Components\IO_Source\mechatronics\BrushlessMotor.fcfx | E33: MECHATRONICS | J33: 1 | K33: 1 | L33: 0 | M33: https://www.flowcode.co.uk/wiki/index.php?title=Component:_ID_dc99e179_216f_4618_aee7_3f5f87541a9d
A34: Bubble Chart | B34: 5D52E8A2-F248-4318-A0AC-E7B9503237CF | C34: BubbleChart.fcpx | D34: Components\IO_Source\2dGDI\ChartBubble.fcfx | E34: FREE | F34: CHARTS | G34: CHARTS | J34: 1 | K34: 1 | L34: 1 | M34: https://www.flowcode.co.uk/wiki/index.php?title=Component:_ID_5d52e8a2_f248_4318_a0ac_e7b9503237cf
A35: Buzzer | B35: 04BBD3B8-EE11-40EB-91E8-1BBBD6F65B8C | C35: Buzzer.fcpx | D35: Components\IO_Source\outputs\Buzzer.fcfx | E35: BASICIO | F35: AUDIO OUTPUT | J35: 1 | K35: 1 | L35: 0 | M35: https://www.flowcode.co.uk/wiki/index.php?title=Component:_ID_04bbd3b8_ee11_40eb_91e8_1bbbd6f65b8c
A36: CAN (Internal MCP2515) | B36: DA332928-6342-4C2C-AFC7-EAF33917D33E | C36: CAN.fcpx | D36: Components\IO_Source\CAN.fcfx | E36: COMMSA | F36: COMMS: INTERFACE | G36: COMMS: INTERFACE | I36: CAN SPI | J36: 1 | K36: 1 | L36: 1 | M36: https://www.flowcode.co.uk/wiki/index.php?title=Component:_ID_da332928_6342_4c2c_afc7_eaf33917d33e
A37: CNC Machine | B37: 93252F96-A8E5-4D65-8C40-11614BB15B52 | C37: CNCMachine.fcpx | D37: Components\IO_Source\mechatronics\Electro Mechanical\CNC Source Files\CNCComponent_v002.fcfx | E37: MODELS | F37: SCENARIOS | J37: 1 | M37: https://www.flowcode.co.uk/wiki/index.php?title=Component:_ID_93252f96_a8e5_4d65_8c40_11614bb15b52
A38: COM Port | B38: CBB3C28E-2D73-4442-AC52-23A3B45D9870 | C38: COMPort.fcpx | D38: Components\IO_Source\Serial_DLL.fcfx | E38: FREE | F38: RUNTIME TOOLS | G38: COMMS: INTERFACE | J38: 1 | K38: 1 | L38: 1 | M38: https://www.flowcode.co.uk/wiki/index.php?title=Component:_ID_cbb3c28e_2d73_4442_ac52_23a3b45d9870
